<?xml version="1.0" ?>
<!-- =================================================================================== -->
<!-- |    This document was autogenerated by xacro from /home/agx/clearpath/robot.urdf.xacro | -->
<!-- |    EDITING THIS FILE BY HAND IS NOT RECOMMENDED                                 | -->
<!-- =================================================================================== -->
<robot name="a200-0791">
  <material name="clearpath_dark_grey">
    <color rgba="0.2 0.2 0.2 1.0"/>
  </material>
  <material name="clearpath_medium_grey">
    <color rgba="0.6 0.6 0.6 1.0"/>
  </material>
  <material name="clearpath_light_grey">
    <color rgba="0.8 0.8 0.8 1.0"/>
  </material>
  <material name="clearpath_yellow">
    <color rgba="0.8 0.8 0.0 1.0"/>
  </material>
  <material name="clearpath_black">
    <color rgba="0.15 0.15 0.15 1.0"/>
  </material>
  <material name="clearpath_white">
    <color rgba="1.0 1.0 1.0 1.0"/>
  </material>
  <material name="clearpath_red">
    <color rgba="1.0 0.0 0.0 1.0"/>
  </material>
  <material name="clearpath_aluminum">
    <color rgba="0.5 0.5 0.5 1"/>
  </material>
  <material name="clearpath_plastic">
    <color rgba="0.1 0.1 0.1   1"/>
  </material>
  <!-- Base link is the center of the robot's bottom plate -->
  <link name="base_link">
    <inertial>
      <mass value="15.0"/>
      <origin xyz="0 0 0.061875"/>
      <inertia ixx="0.65" ixy="0" ixz="0" iyy="1.25" iyz="0" izz="1.35"/>
    </inertial>
    <visual>
      <origin rpy="0 0 0" xyz="0 0 0"/>
      <geometry>
        <mesh filename="D:/Ryan/UM/Academic/Y3SS/Portfolio Project/DRL_Project/robot_model/clearpath_platform_description/meshes/a200/base_link.dae"/>
      </geometry>
      <material name="clearpath_black"/>
    </visual>
    <collision>
      <origin rpy="0 0 0" xyz="0 0 0.061875"/>
      <geometry>
        <box size="0.9874 0.5709 0.12375"/>
      </geometry>
    </collision>
    <collision>
      <origin rpy="0 0 0" xyz="0 0 0.17562499999999998"/>
      <geometry>
        <box size="0.7899200000000001 0.5709 0.10375"/>
      </geometry>
    </collision>
  </link>
  <!-- Base footprint is on the ground under the robot -->
  <link name="base_footprint">
    <inertial>
      <mass value="0.01"/>
      <origin xyz="0 0 0"/>
      <inertia ixx="0.001" ixy="0" ixz="0" iyy="0.001" iyz="0" izz="0.001"/>
    </inertial>
  </link>
  <joint name="base_footprint_joint" type="fixed">
    <origin rpy="0 0 0" xyz="0 0 -0.13228"/>
    <parent link="base_link"/>
    <child link="base_footprint"/>
  </joint>
  <!-- Spawn A200 chassis -->
  <link name="top_chassis_link">
    <inertial>
      <mass value="8.0"/>
      <origin xyz="0 0 0"/>
      <inertia ixx="0.3" ixy="0" ixz="0" iyy="0.5" iyz="0" izz="0.4"/>
    </inertial>
    <visual>
      <origin rpy="0 0 0" xyz="0 0 0"/>
      <geometry>
        <mesh filename="D:/Ryan/UM/Academic/Y3SS/Portfolio Project/DRL_Project/robot_model/clearpath_platform_description/meshes/a200/top_chassis.dae"/>
      </geometry>
      <material name="clearpath_yellow"/>
    </visual>
  </link>
  <!-- Attach chassis to the robot -->
  <joint name="top_chassis_joint" type="fixed">
    <parent link="base_link"/>
    <child link="top_chassis_link"/>
  </joint>
  <!-- Inertial link stores the robot's inertial information -->
  <link name="inertial_link">
    <inertial>
      <mass value="46.034"/>
      <origin xyz="-0.00065 -0.085 0.062"/>
      <inertia ixx="0.6022" ixy="-0.02364" ixz="-0.1197" iyy="1.7386" iyz="-0.001544" izz="2.0296"/>
    </inertial>
  </link>
  <joint name="inertial_joint" type="fixed">
    <origin rpy="0 0 0" xyz="0 0 0"/>
    <parent link="base_link"/>
    <child link="inertial_link"/>
  </joint>
  <link name="front_left_wheel">
    <inertial>
      <mass value="2.637"/>
      <origin xyz="0 0 0"/>
      <inertia ixx="0.02467" ixy="0" ixz="0" iyy="0.04411" iyz="0" izz="0.02467"/>
    </inertial>
    <visual>
      <origin rpy="0 0 0" xyz="0 0 0"/>
      <geometry>
        <mesh filename="D:/Ryan/UM/Academic/Y3SS/Portfolio Project/DRL_Project/robot_model/clearpath_platform_description/meshes/a200/wheel.dae"/>
      </geometry>
      <material name="clearpath_black"/>
    </visual>
    <collision>
      <origin rpy="1.570795 0 0" xyz="0 0 0"/>
      <geometry>
        <cylinder length="0.1143" radius="0.1651"/>
      </geometry>
    </collision>
  </link>
  <!-- <gazebo reference="${wheel_prefix}_wheel">
      <mu1 value="1.0"/>
      <mu2 value="0.5"/>
      <kp value="100000000000000000000.0" />
      <kd value="1.0" />
      <fdir1 value="1 0 0"/>
    </gazebo> -->
  <joint name="front_left_wheel_joint" type="continuous">
    <parent link="base_link"/>
    <child link="front_left_wheel"/>
    <origin rpy="0 0 0" xyz="0.256 0.2775 0.03282"/>
    <axis rpy="0 0 0" xyz="0 1 0"/>
  </joint>
  <link name="front_right_wheel">
    <inertial>
      <mass value="2.637"/>
      <origin xyz="0 0 0"/>
      <inertia ixx="0.02467" ixy="0" ixz="0" iyy="0.04411" iyz="0" izz="0.02467"/>
    </inertial>
    <visual>
      <origin rpy="0 0 0" xyz="0 0 0"/>
      <geometry>
        <mesh filename="D:/Ryan/UM/Academic/Y3SS/Portfolio Project/DRL_Project/robot_model/clearpath_platform_description/meshes/a200/wheel.dae"/>
      </geometry>
      <material name="clearpath_black"/>
    </visual>
    <collision>
      <origin rpy="1.570795 0 0" xyz="0 0 0"/>
      <geometry>
        <cylinder length="0.1143" radius="0.1651"/>
      </geometry>
    </collision>
  </link>
  <!-- <gazebo reference="${wheel_prefix}_wheel">
      <mu1 value="1.0"/>
      <mu2 value="0.5"/>
      <kp value="100000000000000000000.0" />
      <kd value="1.0" />
      <fdir1 value="1 0 0"/>
    </gazebo> -->
  <joint name="front_right_wheel_joint" type="continuous">
    <parent link="base_link"/>
    <child link="front_right_wheel"/>
    <origin rpy="0 0 0" xyz="0.256 -0.2775 0.03282"/>
    <axis rpy="0 0 0" xyz="0 1 0"/>
  </joint>
  <link name="rear_left_wheel">
    <inertial>
      <mass value="2.637"/>
      <origin xyz="0 0 0"/>
      <inertia ixx="0.02467" ixy="0" ixz="0" iyy="0.04411" iyz="0" izz="0.02467"/>
    </inertial>
    <visual>
      <origin rpy="0 0 0" xyz="0 0 0"/>
      <geometry>
        <mesh filename="D:/Ryan/UM/Academic/Y3SS/Portfolio Project/DRL_Project/robot_model/clearpath_platform_description/meshes/a200/wheel.dae"/>
      </geometry>
      <material name="clearpath_black"/>
    </visual>
    <collision>
      <origin rpy="1.570795 0 0" xyz="0 0 0"/>
      <geometry>
        <cylinder length="0.1143" radius="0.1651"/>
      </geometry>
    </collision>
  </link>
  <!-- <gazebo reference="${wheel_prefix}_wheel">
      <mu1 value="1.0"/>
      <mu2 value="0.5"/>
      <kp value="100000000000000000000.0" />
      <kd value="1.0" />
      <fdir1 value="1 0 0"/>
    </gazebo> -->
  <joint name="rear_left_wheel_joint" type="continuous">
    <parent link="base_link"/>
    <child link="rear_left_wheel"/>
    <origin rpy="0 0 0" xyz="-0.256 0.2775 0.03282"/>
    <axis rpy="0 0 0" xyz="0 1 0"/>
  </joint>
  <link name="rear_right_wheel">
    <inertial>
      <mass value="2.637"/>
      <origin xyz="0 0 0"/>
      <inertia ixx="0.02467" ixy="0" ixz="0" iyy="0.04411" iyz="0" izz="0.02467"/>
    </inertial>
    <visual>
      <origin rpy="0 0 0" xyz="0 0 0"/>
      <geometry>
        <mesh filename="D:/Ryan/UM/Academic/Y3SS/Portfolio Project/DRL_Project/robot_model/clearpath_platform_description/meshes/a200/wheel.dae"/>
      </geometry>
      <material name="clearpath_black"/>
    </visual>
    <collision>
      <origin rpy="1.570795 0 0" xyz="0 0 0"/>
      <geometry>
        <cylinder length="0.1143" radius="0.1651"/>
      </geometry>
    </collision>
  </link>
  <!-- <gazebo reference="${wheel_prefix}_wheel">
      <mu1 value="1.0"/>
      <mu2 value="0.5"/>
      <kp value="100000000000000000000.0" />
      <kd value="1.0" />
      <fdir1 value="1 0 0"/>
    </gazebo> -->
  <joint name="rear_right_wheel_joint" type="continuous">
    <parent link="base_link"/>
    <child link="rear_right_wheel"/>
    <origin rpy="0 0 0" xyz="-0.256 -0.2775 0.03282"/>
    <axis rpy="0 0 0" xyz="0 1 0"/>
  </joint>
  <gazebo>
    <plugin filename="libignition-gazebo-wheel-slip-system.so" name="ignition::gazebo::systems::WheelSlip">
      <wheel link_name="front_left_wheel">
        <slip_compliance_lateral>1.0</slip_compliance_lateral>
        <slip_compliance_longitudinal>1.0</slip_compliance_longitudinal>
        <wheel_normal_force>113</wheel_normal_force>
        <wheel_radius>0.1651</wheel_radius>
      </wheel>
      <wheel link_name="front_right_wheel">
        <slip_compliance_lateral>1.0</slip_compliance_lateral>
        <slip_compliance_longitudinal>1.0</slip_compliance_longitudinal>
        <wheel_normal_force>113</wheel_normal_force>
        <wheel_radius>0.1651</wheel_radius>
      </wheel>
      <wheel link_name="rear_left_wheel">
        <slip_compliance_lateral>1.0</slip_compliance_lateral>
        <slip_compliance_longitudinal>1.0</slip_compliance_longitudinal>
        <wheel_normal_force>113</wheel_normal_force>
        <wheel_radius>0.1651</wheel_radius>
      </wheel>
      <wheel link_name="rear_right_wheel">
        <slip_compliance_lateral>1.0</slip_compliance_lateral>
        <slip_compliance_longitudinal>1.0</slip_compliance_longitudinal>
        <wheel_normal_force>113</wheel_normal_force>
        <wheel_radius>0.1651</wheel_radius>
      </wheel>
    </plugin>
  </gazebo>
  <!-- Front bumper mount -->
  <link name="front_bumper_mount">
    <inertial>
      <mass value="0.1"/>
      <origin xyz="0 0 0"/>
      <inertia ixx="0.001" ixy="0" ixz="0" iyy="0.001" iyz="0" izz="0.001"/>
    </inertial>
  </link>
  <joint name="front_bumper_mount_joint" type="fixed">
    <origin rpy="0 0 0" xyz="0.406 0 0.091"/>
    <parent link="base_link"/>
    <child link="front_bumper_mount"/>
  </joint>
  <!-- Rear bumper mount -->
  <link name="rear_bumper_mount">
    <inertial>
      <mass value="0.1"/>
      <origin xyz="0 0 0"/>
      <inertia ixx="0.001" ixy="0" ixz="0" iyy="0.001" iyz="0" izz="0.001"/>
    </inertial>
  </link>
  <joint name="rear_bumper_mount_joint" type="fixed">
    <origin rpy="0 0 3.14159" xyz="-0.406 0 0.091"/>
    <parent link="base_link"/>
    <child link="rear_bumper_mount"/>
  </joint>
  <!-- Default mount -->
  <link name="default_mount">
    <inertial>
      <mass value="0.1"/>
      <origin xyz="0 0 0"/>
      <inertia ixx="0.001" ixy="0" ixz="0" iyy="0.001" iyz="0" izz="0.001"/>
    </inertial>
  </link>
  <joint name="default_mount_joint" type="fixed">
    <child link="default_mount"/>
    <parent link="base_link"/>
    <origin xyz="0.0 0.0 0.224"/>
  </joint>
  <ros2_control name="a200_hardware" type="system">
    <hardware>
      <plugin>clearpath_hardware_interfaces/A200Hardware</plugin>
      <param name="wheel_diameter">0.3302</param>
      <param name="max_accel">5.0</param>
      <param name="max_speed">1.0</param>
      <param name="polling_timeout">0.1</param>
      <param name="serial_port">/dev/clearpath/prolific</param>
    </hardware>
    <joint name="front_left_wheel_joint">
      <command_interface name="velocity">
        <param name="min">-1</param>
        <param name="max">1</param>
      </command_interface>
      <state_interface name="position"/>
      <state_interface name="velocity"/>
    </joint>
    <joint name="rear_left_wheel_joint">
      <command_interface name="velocity">
        <param name="min">-1</param>
        <param name="max">1</param>
      </command_interface>
      <state_interface name="position"/>
      <state_interface name="velocity"/>
    </joint>
    <joint name="front_right_wheel_joint">
      <command_interface name="velocity">
        <param name="min">-1</param>
        <param name="max">1</param>
      </command_interface>
      <state_interface name="position"/>
      <state_interface name="velocity"/>
    </joint>
    <joint name="rear_right_wheel_joint">
      <command_interface name="velocity">
        <param name="min">-1</param>
        <param name="max">1</param>
      </command_interface>
      <state_interface name="position"/>
      <state_interface name="velocity"/>
    </joint>
  </ros2_control>
  <!-- Attachments -->
  <!-- Spawn bumper link -->
  <link name="front_bumper_link">
    <inertial>
      <mass value="0.5"/>
      <origin xyz="0 0 0"/>
      <inertia ixx="0.01" ixy="0" ixz="0" iyy="0.01" iyz="0" izz="0.01"/>
    </inertial>
    <visual>
      <geometry>
        <mesh filename="D:/Ryan/UM/Academic/Y3SS/Portfolio Project/DRL_Project/robot_model/clearpath_platform_description/meshes/a200/attachments/bumper.dae"/>
      </geometry>
      <material name="clearpath_black"/>
    </visual>
  </link>
  <link name="front_bumper_base_link">
    <inertial>
      <mass value="0.1"/>
      <origin xyz="0 0 0"/>
      <inertia ixx="0.001" ixy="0" ixz="0" iyy="0.001" iyz="0" izz="0.001"/>
    </inertial>
  </link>
  <joint name="front_bumper_base_joint" type="fixed">
    <origin rpy="0.0 0.0 0.0" xyz="0.0 0.0 0.0"/>
    <parent link="front_bumper_mount"/>
    <child link="front_bumper_base_link"/>
  </joint>
  <!-- Attach bumper -->
  <joint name="front_bumper_joint" type="fixed">
    <origin rpy="0 0 0" xyz="0.075 0 0"/>
    <parent link="front_bumper_base_link"/>
    <child link="front_bumper_link"/>
  </joint>
  <!-- Spawn bumper link -->
  <link name="rear_bumper_link">
    <inertial>
      <mass value="0.5"/>
      <origin xyz="0 0 0"/>
      <inertia ixx="0.01" ixy="0" ixz="0" iyy="0.01" iyz="0" izz="0.01"/>
    </inertial>
    <visual>
      <geometry>
        <mesh filename="D:/Ryan/UM/Academic/Y3SS/Portfolio Project/DRL_Project/robot_model/clearpath_platform_description/meshes/a200/attachments/bumper.dae"/>
      </geometry>
      <material name="clearpath_black"/>
    </visual>
  </link>
  <link name="rear_bumper_base_link">
    <inertial>
      <mass value="0.1"/>
      <origin xyz="0 0 0"/>
      <inertia ixx="0.001" ixy="0" ixz="0" iyy="0.001" iyz="0" izz="0.001"/>
    </inertial>
  </link>
  <joint name="rear_bumper_base_joint" type="fixed">
    <origin rpy="0.0 0.0 0.0" xyz="0.0 0.0 0.0"/>
    <parent link="rear_bumper_mount"/>
    <child link="rear_bumper_base_link"/>
  </joint>
  <!-- Attach bumper -->
  <joint name="rear_bumper_joint" type="fixed">
    <origin rpy="0 0 0" xyz="0.075 0 0"/>
    <parent link="rear_bumper_base_link"/>
    <child link="rear_bumper_link"/>
  </joint>
  <!-- Spawn user rails -->
  <link name="top_plate_user_rail_link">
    <inertial>
      <mass value="1.0"/>
      <origin xyz="0.272 0 0.019"/>
      <inertia ixx="0.01" ixy="0" ixz="0" iyy="0.05" iyz="0" izz="0.05"/>
    </inertial>
    <visual>
      <origin xyz="0.272 0 0.019"/>
      <geometry>
        <mesh filename="D:/Ryan/UM/Academic/Y3SS/Portfolio Project/DRL_Project/robot_model/clearpath_platform_description/meshes/a200/attachments/user_rail.dae"/>
      </geometry>
      <material name="clearpath_dark_grey"/>
    </visual>
  </link>
  <!-- Attach user rails to base link -->
  <joint name="top_plate_user_rail_joint" type="fixed">
    <origin rpy="0.0 0.0 0.0" xyz="0.0 0.0 0.0"/>
    <parent link="default_mount"/>
    <child link="top_plate_user_rail_link"/>
  </joint>
  <!-- Spawn top plate -->
  <link name="top_plate_link">
    <inertial>
      <mass value="2.0"/>
      <origin xyz="0.0812 0 0"/>
      <inertia ixx="0.015" ixy="0" ixz="0" iyy="0.015" iyz="0" izz="0.025"/>
    </inertial>
    <visual>
      <origin rpy="0 0 0" xyz="0.0812 0 0"/>
      <geometry>
        <mesh filename="D:/Ryan/UM/Academic/Y3SS/Portfolio Project/DRL_Project/robot_model/clearpath_platform_description/meshes/a200/attachments/top_plate.dae"/>
      </geometry>
      <material name="clearpath_dark_grey"/>
    </visual>
    <collision>
      <origin rpy="0 0 0" xyz="0.0812 0 0"/>
      <geometry>
        <box size="0.3 0.3 0.02"/>
      </geometry>
      <material name="clearpath_dark_grey"/>
    </collision>
  </link>
  <!-- Attach top plate -->
  <joint name="top_plate_joint" type="fixed">
    <parent link="top_plate_user_rail_link"/>
    <child link="top_plate_link"/>
    <origin rpy="0 0 0" xyz="0 0 0.021"/>
  </joint>
  <!-- Top plate default link -->
  <link name="top_plate_default_mount">
    <inertial>
      <mass value="0.1"/>
      <origin xyz="0 0 0"/>
      <inertia ixx="0.001" ixy="0" ixz="0" iyy="0.001" iyz="0" izz="0.001"/>
    </inertial>
  </link>
  <joint name="top_plate_default_joint" type="fixed">
    <parent link="top_plate_link"/>
    <child link="top_plate_default_mount"/>
    <origin rpy="0 0 0" xyz="0.07987 0 0.00639"/>
  </joint>
  <!-- Top plate front link -->
  <link name="top_plate_front_mount">
    <inertial>
      <mass value="0.1"/>
      <origin xyz="0 0 0"/>
      <inertia ixx="0.001" ixy="0" ixz="0" iyy="0.001" iyz="0" izz="0.001"/>
    </inertial>
  </link>
  <joint name="top_plate_front_joint" type="fixed">
    <parent link="top_plate_link"/>
    <child link="top_plate_front_mount"/>
    <origin rpy="0 0 0" xyz="0.44487 0 0.00639"/>
  </joint>
  <!-- Top plate rear link-->
  <link name="top_plate_rear_mount">
    <inertial>
      <mass value="0.1"/>
      <origin xyz="0 0 0"/>
      <inertia ixx="0.001" ixy="0" ixz="0" iyy="0.001" iyz="0" izz="0.001"/>
    </inertial>
  </link>
  <joint name="top_plate_rear_joint" type="fixed">
    <parent link="top_plate_link"/>
    <child link="top_plate_rear_mount"/>
    <origin rpy="0 0 0" xyz="-0.28513 0 0.00639"/>
  </joint>
  <!-- Spawn the sensor arch link -->
  <link name="sensor_arch_link">
    <inertial>
      <mass value="1.5"/>
      <origin xyz="0 0 0.51"/>
      <inertia ixx="0.08" ixy="0" ixz="0" iyy="0.03" iyz="0" izz="0.10"/>
    </inertial>
    <visual>
      <origin rpy="0 0 0" xyz="0 0 0.51"/>
      <geometry>
        <mesh filename="D:/Ryan/UM/Academic/Y3SS/Portfolio Project/DRL_Project/robot_model/clearpath_platform_description/meshes/a200/attachments/510_mm_sensor_arch.dae"/>
      </geometry>
      <material name="clearpath_dark_grey"/>
    </visual>
    <collision>
      <origin rpy="0 0 0" xyz="0 0 0.51"/>
      <geometry>
        <box size="0.5 0.05 0.05"/>
      </geometry>
    </collision>
  </link>
  <link name="sensor_arch_mount">
    <inertial>
      <mass value="0.1"/>
      <origin xyz="0 0 0"/>
      <inertia ixx="0.001" ixy="0" ixz="0" iyy="0.001" iyz="0" izz="0.001"/>
    </inertial>
  </link>
  <!-- Attach the sensor arch to the top plate -->
  <joint name="sensor_arch_joint" type="fixed">
    <origin rpy="0.0 0.0 0.0" xyz="0.0 0.0 0.0"/>
    <parent link="default_mount"/>
    <child link="sensor_arch_link"/>
  </joint>
  <joint name="sensor_arch_mount_joint" type="fixed">
    <origin rpy="0 0 0" xyz="0 0 0.51"/>
    <parent link="sensor_arch_link"/>
    <child link="sensor_arch_mount"/>
  </joint>
  <!-- Links -->
  <!-- Mounts -->
  <link name="post_0_link">
    <inertial>
      <mass value="0.3"/>
      <origin xyz="0 0 0.0375"/>
      <inertia ixx="0.001" ixy="0" ixz="0" iyy="0.001" iyz="0" izz="0.0005"/>
    </inertial>
    <!-- Left -->
    <visual>
      <material name="clearpath_dark_grey"/>
      <origin xyz="0 0.075 0.0375"/>
      <geometry>
        <box size="0.04 0.02 0.075"/>
      </geometry>
    </visual>
    <collision>
      <origin xyz="0 0.075 0.0375"/>
      <geometry>
        <box size="0.04 0.02 0.075"/>
      </geometry>
    </collision>
    <!-- Right -->
    <visual>
      <material name="clearpath_dark_grey"/>
      <origin xyz="0 -0.075 0.0375"/>
      <geometry>
        <box size="0.04 0.02 0.075"/>
      </geometry>
    </visual>
    <collision>
      <origin xyz="0 -0.075 0.0375"/>
      <geometry>
        <box size="0.04 0.02 0.075"/>
      </geometry>
    </collision>
  </link>
  <link name="post_0_mount">
    <inertial>
      <mass value="0.1"/>
      <origin xyz="0 0 0"/>
      <inertia ixx="0.001" ixy="0" ixz="0" iyy="0.001" iyz="0" izz="0.001"/>
    </inertial>
  </link>
  <joint name="post_0_joint" type="fixed">
    <child link="post_0_link"/>
    <parent link="sensor_arch_mount"/>
    <insert_block name="origin"/>
  </joint>
  <joint name="post_0_mount_joint" type="fixed">
    <child link="post_0_mount"/>
    <parent link="post_0_link"/>
    <origin xyz="0 0 0.075">
      </origin>
  </joint>
  <link name="disk_0_link">
    <inertial>
      <mass value="0.2"/>
      <origin xyz="0 0 0.003"/>
      <inertia ixx="0.001" ixy="0" ixz="0" iyy="0.001" iyz="0" izz="0.0015"/>
    </inertial>
    <visual>
      <material name="clearpath_dark_grey"/>
      <geometry>
        <mesh filename="D:/Ryan/UM/Academic/Y3SS/Portfolio Project/DRL_Project/robot_model/clearpath_mounts_description/meshes/disk.stl"/>
      </geometry>
      <origin rpy="0 0 0" xyz="0 0 0"/>
    </visual>
    <collision>
      <geometry>
        <box size="0.104 0.142 0.006"/>
      </geometry>
      <origin rpy="0 0 0" xyz="0 0 0.003"/>
    </collision>
  </link>
  <link name="disk_0_mount">
    <inertial>
      <mass value="0.1"/>
      <origin xyz="0 0 0"/>
      <inertia ixx="0.001" ixy="0" ixz="0" iyy="0.001" iyz="0" izz="0.001"/>
    </inertial>
  </link>
  <joint name="disk_0_joint" type="fixed">
    <parent link="post_0_mount"/>
    <child link="disk_0_link"/>
    <origin rpy="0.0 0.0 0.0" xyz="0.0 0.0 0.0"/>
  </joint>
  <joint name="disk_0_mount_joint" type="fixed">
    <parent link="disk_0_link"/>
    <child link="disk_0_mount"/>
    <origin rpy="0 0 0" xyz="0 0 0.006"/>
  </joint>
  <!-- Sensors -->
  <link name="lidar3d_0_link">
    <inertial>
      <mass value="0.83"/>
      <origin xyz="0 0 0.03585"/>
      <inertia ixx="0.000908059425" ixy="0" ixz="0" iyy="0.000908059425" iyz="0" izz="0.0011049624"/>
    </inertial>
    <visual>
      <geometry>
        <mesh filename="D:/Ryan/UM/Academic/Y3SS/Portfolio Project/DRL_Project/robot_model/velodyne_description/meshes/VLP16_base_1.dae"/>
      </geometry>
      <material name="clearpath_light_grey"/>
    </visual>
    <visual>
      <geometry>
        <mesh filename="D:/Ryan/UM/Academic/Y3SS/Portfolio Project/DRL_Project/robot_model/velodyne_description/meshes/VLP16_base_2.dae"/>
      </geometry>
      <material name="clearpath_light_grey"/>
    </visual>
    <collision>
      <origin rpy="0 0 0" xyz="0 0 0.03585"/>
      <geometry>
        <cylinder length="0.0717" radius="0.0516"/>
      </geometry>
    </collision>
  </link>
  <joint name="lidar3d_0_joint" type="fixed">
    <origin rpy="0.0 0.0 0.0" xyz="0.0 0.0 0.0"/>
    <parent link="disk_0_mount"/>
    <child link="lidar3d_0_link"/>
  </joint>
  <link name="lidar3d_0_laser">
    <inertial>
      <mass value="0.01"/>
      <origin xyz="0 0 0"/>
      <inertia ixx="1e-7" ixy="0" ixz="0" iyy="1e-7" iyz="0" izz="1e-7"/>
    </inertial>
    <visual>
      <origin xyz="0 0 -0.0377"/>
      <geometry>
        <mesh filename="D:/Ryan/UM/Academic/Y3SS/Portfolio Project/DRL_Project/robot_model/velodyne_description/meshes/VLP16_scan.dae"/>
      </geometry>
      <material name="clearpath_light_grey"/>
    </visual>
  </link>
  <joint name="lidar3d_0_laser_joint" type="fixed">
    <origin rpy="0 0 0" xyz="0 0 0.0377"/>
    <parent link="lidar3d_0_link"/>
    <child link="lidar3d_0_laser"/>
  </joint>
  <gazebo reference="lidar3d_0_laser">
    <sensor name="lidar3d_0" type="gpu_lidar">
      <update_rate>50</update_rate>
      <visualize>true</visualize>
      <always_on>true</always_on>
      <ignition_frame_id>lidar3d_0_laser</ignition_frame_id>
      <topic>/sensors/lidar3d_0/scan</topic>
      <lidar>
        <scan>
          <horizontal>
            <samples>900</samples>
            <resolution>1</resolution>
            <min_angle>-3.141592</min_angle>
            <max_angle>3.141592</max_angle>
          </horizontal>
          <vertical>
            <samples>15</samples>
            <resolution>1</resolution>
            <min_angle>-0.261799</min_angle>
            <max_angle>0.261799</max_angle>
          </vertical>
        </scan>
        <range>
          <min>0.9</min>
          <max>130.0</max>
          <resolution>0.01</resolution>
        </range>
      </lidar>
    </sensor>
  </gazebo>
  <link name="imu_0_base_link">
    <inertial>
      <mass value="0.01"/>
      <origin xyz="0 0 0"/>
      <inertia ixx="0.0001" ixy="0" ixz="0" iyy="0.0001" iyz="0" izz="0.0001"/>
    </inertial>
  </link>
  <link name="imu_0_link">
    <inertial>
      <mass value="0.015"/>
      <origin xyz="0 0 0.00125"/>
      <inertia ixx="0.00001" ixy="0" ixz="0" iyy="0.00001" iyz="0" izz="0.00001"/>
    </inertial>
    <visual>
      <geometry>
        <box size="0.02 0.02 0.005"/>
      </geometry>
      <material name="clearpath_dark_grey"/>
    </visual>
  </link>
  <joint name="imu_0_base_joint" type="fixed">
    <origin rpy="3.142 0.0 1.571" xyz="-0.05 -0.165 0.085"/>
    <parent link="base_link"/>
    <child link="imu_0_base_link"/>
  </joint>
  <joint name="imu_0_joint" type="fixed">
    <origin xyz="0 0 0.0025"/>
    <parent link="imu_0_base_link"/>
    <child link="imu_0_link"/>
  </joint>
  <gazebo reference="imu_0_link">
    <sensor name="imu_0" type="imu">
      <always_on>true</always_on>
      <update_rate>100</update_rate>
      <visualize>true</visualize>
      <ignition_frame_id>imu_0_link</ignition_frame_id>
      <topic>/sensors/imu_0/data</topic>
    </sensor>
  </gazebo>
  <link name="imu_1_base_link">
    <inertial>
      <mass value="0.01"/>
      <origin xyz="0 0 0"/>
      <inertia ixx="0.0001" ixy="0" ixz="0" iyy="0.0001" iyz="0" izz="0.0001"/>
    </inertial>
  </link>
  <link name="imu_1_link">
    <inertial>
      <mass value="0.015"/>
      <origin xyz="0 0 0.00125"/>
      <inertia ixx="0.00001" ixy="0" ixz="0" iyy="0.00001" iyz="0" izz="0.00001"/>
    </inertial>
    <visual>
      <geometry>
        <box size="0.02 0.02 0.005"/>
      </geometry>
      <material name="clearpath_dark_grey"/>
    </visual>
  </link>
  <joint name="imu_1_base_joint" type="fixed">
    <origin rpy="3.142 0.0 0.0" xyz="0.01 -0.165 0.085"/>
    <parent link="base_link"/>
    <child link="imu_1_base_link"/>
  </joint>
  <joint name="imu_1_joint" type="fixed">
    <origin xyz="0 0 0.0025"/>
    <parent link="imu_1_base_link"/>
    <child link="imu_1_link"/>
  </joint>
  <gazebo reference="imu_1_link">
    <sensor name="imu_1" type="imu">
      <always_on>true</always_on>
      <update_rate>100</update_rate>
      <visualize>true</visualize>
      <ignition_frame_id>imu_1_link</ignition_frame_id>
      <topic>/sensors/imu_1/data</topic>
    </sensor>
  </gazebo>
  <link name="gps_0_link">
    <inertial>
      <mass value="0.25"/>
      <origin xyz="0.0000 -0.0000 0.0324"/>
      <inertia ixx="0.0005" ixy="0" ixz="0" iyy="0.0005" iyz="0" izz="0.0005"/>
    </inertial>
    <visual>
      <material name="clearpath_white"/>
      <geometry>
        <mesh filename="D:/Ryan/UM/Academic/Y3SS/Portfolio Project/DRL_Project/robot_model/clearpath_sensors_description/meshes/swift_antenna.stl"/>
      </geometry>
    </visual>
    <collision>
      <material name="clearpath_white"/>
      <origin xyz="0.0000 -0.0000 0.0324"/>
      <geometry>
        <sphere radius="0.1122"/>
      </geometry>
    </collision>
  </link>
  <joint name="gps_0_joint" type="fixed">
    <child link="gps_0_link"/>
    <parent link="sensor_arch_mount"/>
    <origin rpy="0.0 0.0 0.0" xyz="0.0 -0.371 0.0"/>
  </joint>
  <gazebo reference="gps_0_link">
    <sensor name="gps_0" type="navsat">
      <always_on>1</always_on>
      <update_rate>1</update_rate>
      <ignition_frame_id>gps_0_link</ignition_frame_id>
      <topic>/sensors/gps_0/navsat</topic>
    </sensor>
  </gazebo>
  <link name="gps_1_link">
    <inertial>
      <mass value="0.25"/>
      <origin xyz="0.0000 -0.0000 0.0324"/>
      <inertia ixx="0.0005" ixy="0" ixz="0" iyy="0.0005" iyz="0" izz="0.0005"/>
    </inertial>
    <visual>
      <material name="clearpath_white"/>
      <geometry>
        <mesh filename="D:/Ryan/UM/Academic/Y3SS/Portfolio Project/DRL_Project/robot_model/clearpath_sensors_description/meshes/swift_antenna.stl"/>
      </geometry>
    </visual>
    <collision>
      <material name="clearpath_white"/>
      <origin xyz="0.0000 -0.0000 0.0324"/>
      <geometry>
        <sphere radius="0.1122"/>
      </geometry>
    </collision>
  </link>
  <joint name="gps_1_joint" type="fixed">
    <child link="gps_1_link"/>
    <parent link="sensor_arch_mount"/>
    <origin rpy="0.0 0.0 0.0" xyz="0.0 0.371 0.0"/>
  </joint>
  <gazebo reference="gps_1_link">
    <sensor name="gps_1" type="navsat">
      <always_on>1</always_on>
      <update_rate>1</update_rate>
      <ignition_frame_id>gps_1_link</ignition_frame_id>
      <topic>/sensors/gps_1/navsat</topic>
    </sensor>
  </gazebo>
  <!-- Manipulators -->
  <!-- Extras -->
  <!-- 
    This file manually defines the base links and joints for all four cameras.
    This version uses the official ZED X 3D models (meshes) and materials for a realistic look in RViz.
  -->
  <!-- The main mount point for all cameras. This attaches to the robot's main body. -->
  <link name="multi_camera_mount_link">
    <inertial>
      <mass value="0.1"/>
      <origin xyz="0 0 0"/>
      <inertia ixx="0.001" ixy="0" ixz="0" iyy="0.001" iyz="0" izz="0.001"/>
    </inertial>
  </link>
  <!-- Attach the camera mount to the robot's default_mount frame -->
  <joint name="multi_camera_mount_joint" type="fixed">
    <parent link="default_mount"/>
    <child link="multi_camera_mount_link"/>
    <origin rpy="0 0 0" xyz="0 0 0"/>
  </joint>
  <material name="zed_mat">
    <color rgba="0.8 0.8 0.8 1.0"/>
  </material>
  <material name="zedm_mat">
    <color rgba="0 0 0 1.0"/>
  </material>
  <material name="zed2_mat">
    <color rgba="0.25 0.25 0.25 1.0"/>
  </material>
  <material name="zed2i_mat">
    <color rgba="0.25 0.25 0.25 1.0"/>
  </material>
  <material name="zedx_mat">
    <color rgba="0.25 0.25 0.25 1.0"/>
  </material>
  <material name="zedxm_mat">
    <color rgba="0.25 0.25 0.25 1.0"/>
  </material>
  <material name="virtual_mat">
    <color rgba="0.25 0.25 0.25 1.0"/>
  </material>
  <material name="zedxonegs_mat">
    <color rgba="0.25 0.25 0.25 1.0"/>
  </material>
  <material name="zedxone4k_mat">
    <color rgba="0.25 0.25 0.25 1.0"/>
  </material>
  <!-- 
    Manually define the link and joint for each camera.
    The visual tag now points to the ZED X .stl file for a realistic model.
    
    IMPORTANT: Update the xyz and rpy values below to match the physical location of your cameras.
  -->
  <!-- Front Camera -->
  <link name="front_zed_camera_link">
    <inertial>
      <mass value="0.2"/>
      <origin xyz="0 0 0"/>
      <inertia ixx="0.001" ixy="0" ixz="0" iyy="0.001" iyz="0" izz="0.001"/>
    </inertial>
    <visual>
      <geometry>
        <!-- Use the official 3D model for the ZED X -->
        <mesh filename="D:/Ryan/UM/Academic/Y3SS/Portfolio Project/DRL_Project/robot_model/zed_msgs/meshes/zedx.stl"/>
      </geometry>
      <!-- Use the official material definition for the ZED X -->
      <material name="zedx_mat"/>
    </visual>
  </link>
  <joint name="front_zed_camera_joint" type="fixed">
    <parent link="multi_camera_mount_link"/>
    <child link="front_zed_camera_link"/>
    <origin rpy="0.0 0.349 0.0" xyz="0.07 0.0 0.45"/>
  </joint>
  <!-- Right Camera -->
  <link name="right_zed_camera_link">
    <inertial>
      <mass value="0.2"/>
      <origin xyz="0 0 0"/>
      <inertia ixx="0.001" ixy="0" ixz="0" iyy="0.001" iyz="0" izz="0.001"/>
    </inertial>
    <visual>
      <geometry>
        <mesh filename="D:/Ryan/UM/Academic/Y3SS/Portfolio Project/DRL_Project/robot_model/zed_msgs/meshes/zedx.stl"/>
      </geometry>
      <material name="zedx_mat"/>
    </visual>
  </link>
  <joint name="right_zed_camera_joint" type="fixed">
    <parent link="multi_camera_mount_link"/>
    <child link="right_zed_camera_link"/>
    <origin rpy="0.0 0.576 -1.57" xyz="0.0 -0.35 0.45"/>
  </joint>
  <!-- Back Camera -->
  <link name="back_zed_camera_link">
    <inertial>
      <mass value="0.2"/>
      <origin xyz="0 0 0"/>
      <inertia ixx="0.001" ixy="0" ixz="0" iyy="0.001" iyz="0" izz="0.001"/>
    </inertial>
    <visual>
      <geometry>
        <mesh filename="D:/Ryan/UM/Academic/Y3SS/Portfolio Project/DRL_Project/robot_model/zed_msgs/meshes/zedx.stl"/>
      </geometry>
      <material name="zedx_mat"/>
    </visual>
  </link>
  <joint name="back_zed_camera_joint" type="fixed">
    <parent link="multi_camera_mount_link"/>
    <child link="back_zed_camera_link"/>
    <origin rpy="0.0 0.314 3.14" xyz="-0.07 0.0 0.43"/>
  </joint>
  <!-- Left Camera -->
  <link name="left_zed_camera_link">
    <inertial>
      <mass value="0.2"/>
      <origin xyz="0 0 0"/>
      <inertia ixx="0.001" ixy="0" ixz="0" iyy="0.001" iyz="0" izz="0.001"/>
    </inertial>
    <visual>
      <geometry>
        <mesh filename="D:/Ryan/UM/Academic/Y3SS/Portfolio Project/DRL_Project/robot_model/zed_msgs/meshes/zedx.stl"/>
      </geometry>
      <material name="zedx_mat"/>
    </visual>
  </link>
  <joint name="left_zed_camera_joint" type="fixed">
    <parent link="multi_camera_mount_link"/>
    <child link="left_zed_camera_link"/>
    <origin rpy="0.0 0.576 1.57" xyz="0.0 0.35 0.45"/>
  </joint>
</robot>